using Auth.Core.DTOs;
using Auth.Core.Services;
using Microsoft.AspNetCore.Authorization;
using Microsoft.AspNetCore.Http;
using Microsoft.AspNetCore.Mvc;
using SharedLibrary.Exceptions;
using System.Threading.Tasks;

namespace AuthAPI.Controllers
{
    [Route("api/[controller]")]
    [ApiController]
    public class UserController : CustomBaseController
    {
        private readonly IUserService _userService;

        public UserController(IUserService userService)
        {
            _userService = userService;
        }

        //api/user
        [HttpPost]
        public async Task<IActionResult> CreateUser(CreateUserDto createUserDto)
        {
            throw new CustomException("Veri tabanı ile ilgili bir hata meydana geldi"); //bu satırda customexceptionu kullandım artık hata fırtlatıyorum.
            return ActionResultInstance(await _userService.CreateUserAsync(createUserDto));
        }

        [Authorize]
        [HttpGet]
        public async Task<IActionResult> GetUser()
        {
            return ActionResultInstance(await _userService.GetUserByNameAsync(HttpContext.User.Identity.Name));
        }
    }
}
